Workbook

Sheet Ficha Resumen del Proyecto
B2: CONDOMINIO ECOLOGICO RÚSTICO DE LUJO - MOON PARACAS
B3: Ficha Resumen de Áreas, Tipologías y Parámetros Técnicos de Ingeniería
B5: 1. CUADRO RESUMEN DE DISTRIBUCIÓN DE ÁREAS (11.2 Hectáreas)
B6: Componente del Masterplan | C6: Área (m²) | D6: Porcentaje (%) | E6: Descripción Técnica
B7: Área Útil Vendible (Lotes y Cocheras) | C7: =E21+E27 | D7: =C7/$C$12 | E7: Superficie neta asignada a parcelas privadas de vivienda.
B8: Área Aportes (Amenidades / Oasis) | C8: 21149.13 | D8: =C8/$C$12 | E8: Parques comunes, piscina tipo oasis, espejo de agua y senderos Zen.
B9: Vías y Faja de Servidumbre | C9: 17137.84 | D9: =C9/$C$12 | E9: Vías de circulación interna de 6.0m de ancho y fajas peatonales.
B10: Retiro Perimetral y Residual | C10: 10107.39 | D10: =C10/$C$12 | E10: Margen de seguridad perimetral de amortiguamiento frente al entorno exterior.
B11: Buffer de Expansión / Reserva Técnica | C11: 5084.83 | D11: =C11/$C$12 | E11: Margen técnico de tierras liberado tras la re-ingeniería de cabidas útiles.
B12: ÁREA TOTAL TERRENO (MATRIZ) | C12: =SUM(C7:C11) | D12: =SUM(D7:D11) | E12: Validado matemáticamente al 100.00%
B14: 2. INVENTARIO RESUMEN DE LOTES COMERCIALES
B15: Tipología de Lote | C15: Lotes Vendibles | D15: Área Promedio (m²) | E15: Área Total (m²) | F15: Precio Base x m² | G15: Recaudación Proyectada
B16: Lote Premium (Oasis) | C16: =COUNTIF('Inventario Detallado'!D:D, "Lote Premium (Oasis)") | D16: =AVERAGEIF('Inventario Detallado'!D:D, "Lote Premium (Oasis)", 'Inventario Detallado'!E:E) | E16: =SUMIF('Inventario Detallado'!D:D, "Lote Premium (Oasis)", 'Inventario Detallado'!E:E) | F16: S/ 170/m² (Fase Estándar) | G16: =SUMIF('Inventario Detallado'!D:D, "Lote Premium (Oasis)", 'Inventario Detallado'!G:G)
B17: Lote Zen | C17: =COUNTIF('Inventario Detallado'!D:D, "Lote Zen") | D17: =AVERAGEIF('Inventario Detallado'!D:D, "Lote Zen", 'Inventario Detallado'!E:E) | E17: =SUMIF('Inventario Detallado'!D:D, "Lote Zen", 'Inventario Detallado'!E:E) | F17: S/ 120/m² (Fase Estándar) | G17: =SUMIF('Inventario Detallado'!D:D, "Lote Zen", 'Inventario Detallado'!G:G)
B18: Lote Estándar | C18: =COUNTIF('Inventario Detallado'!D:D, "Lote Estándar") | D18: =AVERAGEIF('Inventario Detallado'!D:D, "Lote Estándar", 'Inventario Detallado'!E:E) | E18: =SUMIF('Inventario Detallado'!D:D, "Lote Estándar", 'Inventario Detallado'!E:E) | F18: S/ 120/m² (Fase Estándar) | G18: =SUMIF('Inventario Detallado'!D:D, "Lote Estándar", 'Inventario Detallado'!G:G)
B19: Lote Tiny House | C19: =COUNTIF('Inventario Detallado'!D:D, "Lote Tiny House") | D19: =AVERAGEIF('Inventario Detallado'!D:D, "Lote Tiny House", 'Inventario Detallado'!E:E) | E19: =SUMIF('Inventario Detallado'!D:D, "Lote Tiny House", 'Inventario Detallado'!E:E) | F19: S/ 120/m² (Fase Estándar) | G19: =SUMIF('Inventario Detallado'!D:D, "Lote Tiny House", 'Inventario Detallado'!G:G)
B20: Lote Ajuste (Irregular) | C20: =COUNTIF('Inventario Detallado'!D:D, "Lote Ajuste (Irregular)") | D20: =AVERAGEIF('Inventario Detallado'!D:D, "Lote Ajuste (Irregular)", 'Inventario Detallado'!E:E) | E20: =SUMIF('Inventario Detallado'!D:D, "Lote Ajuste (Irregular)", 'Inventario Detallado'!E:E) | F20: S/ 120/m² (Fase Estándar) | G20: =SUMIF('Inventario Detallado'!D:D, "Lote Ajuste (Irregular)", 'Inventario Detallado'!G:G)
B21: Subtotal Lotes Residenciales | C21: =SUM(C16:C20) | D21: =AVERAGEIF('Inventario Detallado'!D:D, "Lote*", 'Inventario Detallado'!E:E) | E21: =SUM(E16:E20) | G21: =SUM(G16:G20)
B23: 3. COMPONENTE DE ESTACIONAMIENTOS INTERNOS Y EXTERNOS
B24: Tipo de Cochera | C24: Unidades | D24: Área Unit. (m²) | E24: Área Total (m²) | F24: Precio Venta (S/) | G24: Recaudación Proyectada
B25: Cochera Plus (Propiedad Privada) | C25: =COUNTIF('Inventario Detallado'!D:D, "Cochera Plus") | D25: 12.5 | E25: =SUMIF('Inventario Detallado'!D:D, "Cochera Plus", 'Inventario Detallado'!E:E) | F25: 5000 | G25: =SUMIF('Inventario Detallado'!D:D, "Cochera Plus", 'Inventario Detallado'!G:G)
B26: Cochera Visitas (Pública / Libre de Pago) | C26: =COUNTIF('Inventario Detallado'!D:D, "Cochera Visitas (Pública)") | D26: 12.5 | E26: =SUMIF('Inventario Detallado'!D:D, "Cochera Visitas (Pública)", 'Inventario Detallado'!E:E) | F26: 0 | G26: 0
B27: Subtotal Estacionamientos | C27: =SUM(C25:C26) | E27: =SUM(E25:E26) | G27: =SUM(G25:G26)
B29: RECAUDACIÓN Y VALORIZACIÓN CONSOLIDADA
B30: Recaudación Proyectada Lotes | G30: =G21
B31: Recaudación Proyectada Cocheras Privadas | G31: =G27
B32: PROYECCIÓN TOTAL BRUTA DEL PROYECTO (100% VENDIDO) | G32: =G30+G31

Sheet Lotes Disponibles
B2: CONDOMINIO ECOLOGICO RÚSTICO DE LUJO - MOON PARACAS
B3: Inventario Técnico de Lotes Disponibles y en Oferta Especial
B5: LOTES DISPONIBLES | D5: ÁREA DISPONIBLE (m²) | F5: VALOR COMERCIAL (S/) | H5: VALOR TOTAL DE OBRA (S/)
B6: =COUNTIF('Inventario Detallado'!J2:J451, "Disponible") + COUNTIF('Inventario Detallado'!J2:J451, "En Oferta") | D6: =SUMIF('Inventario Detallado'!J2:J451, "Disponible", 'Inventario Detallado'!E2:E451) + SUMIF('Inventario Detallado'!J2:J451, "En Oferta", 'Inventario Detallado'!E2:E451) | F6: =SUMIF('Inventario Detallado'!J2:J451, "Disponible", 'Inventario Detallado'!G2:G451) + SUMIF('Inventario Detallado'!J2:J451, "En Oferta", 'Inventario Detallado'!G2:G451) | H6: ='Presupuesto de Obras'!G37
A9: ID Lote | B9: Nombre Comercial | C9: Manzana | D9: Tipología | E9: Área útil (m²) | F9: Dimensiones | G9: Precio Venta (S/) | H9: Dist. Oasis (m) | I9: Dist. Cocheras (m) | J9: Estado Comercial
A10: L001 | B10: Lote 1 | C10: M1 | D10: Lote Estándar | E10: ='Inventario Detallado'!E2 | F10: 12.16m x 18.75m | G10: ='Inventario Detallado'!G2 | H10: 106 | I10: 14 | J10: Disponible
A11: L002 | B11: Lote 2 | C11: M1 | D11: Lote Estándar | E11: ='Inventario Detallado'!E3 | F11: 12.16m x 18.67m | G11: ='Inventario Detallado'!G3 | H11: 106 | I11: 26 | J11: Disponible
A12: L003 | B12: Lote 3 | C12: M1 | D12: Lote Estándar | E12: ='Inventario Detallado'!E4 | F12: 12.16m x 18.64m | G12: ='Inventario Detallado'!G4 | H12: 106 | I12: 39 | J12: Disponible
A13: L004 | B13: Lote 4 | C13: M1 | D13: Lote Estándar | E13: ='Inventario Detallado'!E5 | F13: 12.18m x 18.66m | G13: ='Inventario Detallado'!G5 | H13: 107 | I13: 51 | J13: Disponible
A14: L006 | B14: Lote 6 | C14: M1 | D14: Lote Estándar | E14: ='Inventario Detallado'!E7 | F14: 12.18m x 18.86m | G14: ='Inventario Detallado'!G7 | H14: 109 | I14: 75 | J14: Disponible
A15: L007 | B15: Lote 7 | C15: M1 | D15: Lote Estándar | E15: ='Inventario Detallado'!E8 | F15: 12.18m x 19.02m | G15: ='Inventario Detallado'!G8 | H15: 110 | I15: 88 | J15: Disponible
A16: L008 | B16: Lote 8 | C16: M2 | D16: Lote Estándar | E16: ='Inventario Detallado'!E9 | F16: 12.07m x 19.26m | G16: ='Inventario Detallado'!G9 | H16: 112 | I16: 105 | J16: Disponible
A17: L009 | B17: Lote 9 | C17: M2 | D17: Lote Estándar | E17: ='Inventario Detallado'!E10 | F17: 12.07m x 19.34m | G17: ='Inventario Detallado'!G10 | H17: 112 | I17: 117 | J17: Disponible
A18: L010 | B18: Lote 10 | C18: M2 | D18: Lote Estándar | E18: ='Inventario Detallado'!E11 | F18: 12.07m x 19.37m | G18: ='Inventario Detallado'!G11 | H18: 112 | I18: 129 | J18: Disponible
A19: L011 | B19: Lote 11 | C19: M2 | D19: Lote Estándar | E19: ='Inventario Detallado'!E12 | F19: 12.07m x 19.39m | G19: ='Inventario Detallado'!G12 | H19: 112 | I19: 141 | J19: Disponible
A20: L012 | B20: Lote 12 | C20: M2 | D20: Lote Estándar | E20: ='Inventario Detallado'!E13 | F20: 12.07m x 19.42m | G20: ='Inventario Detallado'!G13 | H20: 112 | I20: 145 | J20: Disponible
A21: L013 | B21: Lote 13 | C21: M2 | D21: Lote Estándar | E21: ='Inventario Detallado'!E14 | F21: 12.07m x 19.45m | G21: ='Inventario Detallado'!G14 | H21: 112 | I21: 145 | J21: Disponible
A22: L015 | B22: Lote 15 | C22: M2 | D22: Lote Estándar | E22: ='Inventario Detallado'!E16 | F22: 12.07m x 19.50m | G22: ='Inventario Detallado'!G16 | H22: 113 | I22: 145 | J22: Disponible
A23: L016 | B23: Lote 16 | C23: M2 | D23: Lote Estándar | E23: ='Inventario Detallado'!E17 | F23: 12.07m x 19.52m | G23: ='Inventario Detallado'!G17 | H23: 113 | I23: 145 | J23: Disponible
A24: L017 | B24: Lote 17 | C24: M2 | D24: Lote Estándar | E24: ='Inventario Detallado'!E18 | F24: 12.07m x 19.55m | G24: ='Inventario Detallado'!G18 | H24: 112 | I24: 133 | J24: Disponible
A25: L018 | B25: Lote 18 | C25: M3 | D25: Lote Estándar | E25: ='Inventario Detallado'!E19 | F25: 12.54m x 19.53m | G25: ='Inventario Detallado'!G19 | H25: 111 | I25: 115 | J25: Disponible
A26: L019 | B26: Lote 19 | C26: M3 | D26: Lote Estándar | E26: ='Inventario Detallado'!E20 | F26: 12.54m x 19.42m | G26: ='Inventario Detallado'!G20 | H26: 110 | I26: 103 | J26: Disponible
A27: L020 | B27: Lote 20 | C27: M3 | D27: Lote Estándar | E27: ='Inventario Detallado'!E21 | F27: 12.54m x 19.29m | G27: ='Inventario Detallado'!G21 | H27: 109 | I27: 91 | J27: Disponible
A28: L021 | B28: Lote 21 | C28: M3 | D28: Lote Estándar | E28: ='Inventario Detallado'!E22 | F28: 12.54m x 19.19m | G28: ='Inventario Detallado'!G22 | H28: 109 | I28: 78 | J28: Disponible
A29: L022 | B29: Lote 22 | C29: M3 | D29: Lote Estándar | E29: ='Inventario Detallado'!E23 | F29: 12.56m x 19.15m | G29: ='Inventario Detallado'!G23 | H29: 109 | I29: 65 | J29: Disponible
A30: L023 | B30: Lote 23 | C30: M3 | D30: Lote Estándar | E30: ='Inventario Detallado'!E24 | F30: 12.56m x 19.16m | G30: ='Inventario Detallado'!G24 | H30: 110 | I30: 53 | J30: Disponible
A31: L024 | B31: Lote 24 | C31: M3 | D31: Lote Estándar | E31: ='Inventario Detallado'!E25 | F31: 12.56m x 19.22m | G31: ='Inventario Detallado'!G25 | H31: 110 | I31: 40 | J31: Disponible
A32: L025 | B32: Lote 25 | C32: M3 | D32: Lote Estándar | E32: ='Inventario Detallado'!E26 | F32: 12.56m x 19.34m | G32: ='Inventario Detallado'!G26 | H32: 111 | I32: 28 | J32: Disponible
A33: L026 | B33: Lote 26 | C33: M3 | D33: Lote Estándar | E33: ='Inventario Detallado'!E27 | F33: 12.56m x 19.51m | G33: ='Inventario Detallado'!G27 | H33: 113 | I33: 15 | J33: Disponible
... A39: L032 | B39: Lote 32 | C39: M4 | D39: Lote Estándar | E39: ='Inventario Detallado'!E33 | F39: 12.19m x 13.01m | G39: ='Inventario Detallado'!G33 | H39: 85 | I39: 75 | J39: Disponible
A40: L034 | B40: Lote 34 | C40: M5 | D40: Lote Estándar | E40: ='Inventario Detallado'!E35 | F40: 12.07m x 13.28m | G40: ='Inventario Detallado'!G35 | H40: 87 | I40: 105 | J40: Disponible
A41: L035 | B41: Lote 35 | C41: M5 | D41: Lote Estándar | E41: ='Inventario Detallado'!E36 | F41: 12.07m x 13.34m | G41: ='Inventario Detallado'!G36 | H41: 87 | I41: 116 | J41: Disponible
A42: L036 | B42: Lote 36 | C42: M5 | D42: Lote Estándar | E42: ='Inventario Detallado'!E37 | F42: 12.07m x 13.36m | G42: ='Inventario Detallado'!G37 | H42: 87 | I42: 128 | J42: Disponible
A43: L037 | B43: Lote 37 | C43: M5 | D43: Lote Estándar | E43: ='Inventario Detallado'!E38 | F43: 12.07m x 13.38m | G43: ='Inventario Detallado'!G38 | H43: 88 | I43: 140 | J43: Disponible
A44: L038 | B44: Lote 38 | C44: M5 | D44: Lote Estándar | E44: ='Inventario Detallado'!E39 | F44: 12.07m x 13.39m | G44: ='Inventario Detallado'!G39 | H44: 88 | I44: 145 | J44: Disponible
A45: L039 | B45: Lote 39 | C45: M5 | D45: Lote Estándar | E45: ='Inventario Detallado'!E40 | F45: 12.07m x 13.41m | G45: ='Inventario Detallado'!G40 | H45: 88 | I45: 145 | J45: Disponible
A46: L040 | B46: Lote 40 | C46: M5 | D46: Lote Estándar | E46: ='Inventario Detallado'!E41 | F46: 12.07m x 13.43m | G46: ='Inventario Detallado'!G41 | H46: 88 | I46: 145 | J46: Disponible
A47: L041 | B47: Lote 41 | C47: M5 | D47: Lote Estándar | E47: ='Inventario Detallado'!E42 | F47: 12.07m x 13.45m | G47: ='Inventario Detallado'!G42 | H47: 88 | I47: 145 | J47: Disponible
A48: L042 | B48: Lote 42 | C48: M5 | D48: Lote Estándar | E48: ='Inventario Detallado'!E43 | F48: 12.07m x 13.46m | G48: ='Inventario Detallado'!G43 | H48: 88 | I48: 145 | J48: Disponible
A49: L043 | B49: Lote 43 | C49: M5 | D49: Lote Estándar | E49: ='Inventario Detallado'!E44 | F49: 12.07m x 13.48m | G49: ='Inventario Detallado'!G44 | H49: 88 | I49: 133 | J49: Disponible
...

Sheet Inventario Detallado
A1: ID Elemento | B1: Nombre Comercial | C1: Manzana / Bloque | D1: Tipología | E1: Área Útil (m²) | F1: Dimensiones | G1: Precio Venta (S/) | H1: Dist. Oasis (m) | I1: Dist. Cocheras (m) | J1: Estado Comercial
A2: L001 | B2: Lote 1 | C2: M1 | D2: Lote Estándar | E2: 225.54 | F2: 12.16m x 18.75m | G2: =E2*120 | H2: 106 | I2: 14 | J2: Disponible
A3: L002 | B3: Lote 2 | C3: M1 | D3: Lote Estándar | E3: 224.67 | F3: 12.16m x 18.67m | G3: =E3*120 | H3: 106 | I3: 26 | J3: Disponible
A4: L003 | B4: Lote 3 | C4: M1 | D4: Lote Estándar | E4: 224.37 | F4: 12.16m x 18.64m | G4: =E4*120 | H4: 106 | I4: 39 | J4: Disponible
A5: L004 | B5: Lote 4 | C5: M1 | D5: Lote Estándar | E5: 225.14 | F5: 12.18m x 18.66m | G5: =E5*120 | H5: 107 | I5: 51 | J5: Disponible
A6: L005 | B6: Lote 5 | C6: M1 | D6: Lote Estándar | E6: 226.12 | F6: 12.18m x 18.74m | G6: =E6*120 | H6: 108 | I6: 63 | J6: Vendido
A7: L006 | B7: Lote 6 | C7: M1 | D7: Lote Estándar | E7: 227.66 | F7: 12.18m x 18.86m | G7: =E7*120 | H7: 109 | I7: 75 | J7: Disponible
A8: L007 | B8: Lote 7 | C8: M1 | D8: Lote Estándar | E8: 229.65 | F8: 12.18m x 19.02m | G8: =E8*120 | H8: 110 | I8: 88 | J8: Disponible
A9: L008 | B9: Lote 8 | C9: M2 | D9: Lote Estándar | E9: 230.62 | F9: 12.07m x 19.26m | G9: =E9*120 | H9: 112 | I9: 105 | J9: Disponible
A10: L009 | B10: Lote 9 | C10: M2 | D10: Lote Estándar | E10: 231.26 | F10: 12.07m x 19.34m | G10: =E10*120 | H10: 112 | I10: 117 | J10: Disponible
A11: L010 | B11: Lote 10 | C11: M2 | D11: Lote Estándar | E11: 231.58 | F11: 12.07m x 19.37m | G11: =E11*120 | H11: 112 | I11: 129 | J11: Disponible
A12: L011 | B12: Lote 11 | C12: M2 | D12: Lote Estándar | E12: 231.89 | F12: 12.07m x 19.39m | G12: =E12*120 | H12: 112 | I12: 141 | J12: Disponible
A13: L012 | B13: Lote 12 | C13: M2 | D13: Lote Estándar | E13: 232.2 | F13: 12.07m x 19.42m | G13: =E13*120 | H13: 112 | I13: 145 | J13: Disponible
... A60: L059 | B60: Lote 59 | C60: M7 | D60: Lote Tiny House | E60: 115.32 | F60: 12.19m x 9.51m | G60: =E60*120 | H60: 66 | I60: 88 | J60: Disponible
A61: L060 | B61: Lote 60 | C61: M7 | D61: Lote Tiny House | E61: 112.43 | F61: 12.17m x 9.38m | G61: =E61*60 | H61: 55 | I61: 25 | J61: En Oferta
A62: L061 | B62: Lote 61 | C62: M7 | D62: Lote Tiny House | E62: 112.18 | F62: 12.17m x 9.34m | G62: =E62*120 | H62: 54 | I62: 37 | J62: Separado
A63: L062 | B63: Lote 62 | C63: M7 | D63: Lote Tiny House | E63: 112.22 | F63: 12.17m x 9.32m | G63: =E63*60 | H63: 54 | I63: 46 | J63: En Oferta
A64: L063 | B64: Lote 63 | C64: M7 | D64: Lote Tiny House | E64: 112.79 | F64: 12.19m x 9.33m | G64: =E64*120 | H64: 55 | I64: 56 | J64: Disponible
A65: L064 | B65: Lote 64 | C65: M7 | D65: Lote Tiny House | E65: 113.43 | F65: 12.19m x 9.37m | G65: =E65*60 | H65: 55 | I65: 67 | J65: En Oferta
A66: L065 | B66: Lote 65 | C66: M7 | D66: Lote Tiny House | E66: 114.33 | F66: 12.19m x 9.43m | G66: =E66*60 | H66: 56 | I66: 78 | J66: En Oferta
A67: L066 | B67: Lote 66 | C67: M7 | D67: Lote Tiny House | E67: 115.41 | F67: 12.19m x 9.51m | G67: =E67*120 | H67: 57 | I67: 90 | J67: Disponible
A68: L067 | B68: Lote 67 | C68: M8 | D68: Lote Tiny House | E68: 115.71 | F68: 12.07m x 9.63m | G68: =E68*120 | H68: 68 | I68: 105 | J68: Disponible
A69: L068 | B69: Lote 68 | C69: M8 | D69: Lote Tiny House | E69: 115.75 | F69: 12.08m x 9.67m | G69: =E69*120 | H69: 68 | I69: 117 | J69: Disponible
A70: L069 | B70: Lote 69 | C70: M8 | D70: Lote Tiny House | E70: 115.91 | F70: 12.08m x 9.68m | G70: =E70*120 | H70: 68 | I70: 129 | J70: Disponible
A71: L070 | B71: Lote 70 | C71: M8 | D71: Lote Tiny House | E71: 116.06 | F71: 12.08m x 9.70m | G71: =E71*120 | H71: 68 | I71: 141 | J71: Disponible
A72: L071 | B72: Lote 71 | C72: M8 | D72: Lote Tiny House | E72: 116.22 | F72: 12.08m x 9.71m | G72: =E72*120 | H72: 68 | I72: 145 | J72: Disponible
A73: L072 | B73: Lote 72 | C73: M8 | D73: Lote Tiny House | E73: 116.38 | F73: 12.08m x 9.72m | G73: =E73*60 | H73: 68 | I73: 145 | J73: En Oferta
A74: L073 | B74: Lote 73 | C74: M8 | D74: Lote Tiny House | E74: 116.54 | F74: 12.08m x 9.74m | G74: =E74*120 | H74: 68 | I74: 145 | J74: Disponible
A75: L074 | B75: Lote 74 | C75: M8 | D75: Lote Tiny House | E75: 116.69 | F75: 12.08m x 9.75m | G75: =E75*120 | H75: 68 | I75: 145 | J75: Disponible
A76: L075 | B76: Lote 75 | C76: M8 | D76: Lote Tiny House | E76: 116.85 | F76: 12.08m x 9.76m | G76: =E76*120 | H76: 68 | I76: 145 | J76: Disponible
A77: L076 | B77: Lote 76 | C77: M8 | D77: Lote Tiny House | E77: 117.01 | F77: 12.08m x 9.77m | G77: =E77*120 | H77: 68 | I77: 133 | J77: Disponible
A78: L077 | B78: Lote 77 | C78: M8 | D78: Lote Tiny House | E78: 115.79 | F78: 12.07m x 9.63m | G78: =E78*60 | H78: 58 | I78: 106 | J78: En Oferta
A79: L078 | B79: Lote 78 | C79: M8 | D79: Lote Tiny House | E79: 115.78 | F79: 12.08m x 9.67m | G79: =E79*120 | H79: 58 | I79: 118 | J79: Disponible
A80: L079 | B80: Lote 79 | C80: M8 | D80: Lote Tiny House | E80: 115.94 | F80: 12.08m x 9.68m | G80: =E80*120 | H80: 58 | I80: 129 | J80: Disponible
A81: L080 | B81: Lote 80 | C81: M8 | D81: Lote Tiny House | E81: 116.09 | F81: 12.08m x 9.70m | G81: =E81*60 | H81: 58 | I81: 141 | J81: En Oferta
A82: L081 | B82: Lote 81 | C82: M8 | D82: Lote Tiny House | E82: 116.25 | F82: 12.08m x 9.71m | G82: =E82*120 | H82: 58 | I82: 145 | J82: Separado
A83: L082 | B83: Lote 82 | C83: M8 | D83: Lote Tiny House | E83: 116.41 | F83: 12.08m x 9.72m | G83: =E83*60 | H83: 58 | I83: 145 | J83: En Oferta
A84: L083 | B84: Lote 83 | C84: M8 | D84: Lote Tiny House | E84: 116.57 | F84: 12.08m x 9.74m | G84: =E84*120 | H84: 58 | I84: 145 | J84: Disponible
A85: L084 | B85: Lote 84 | C85: M8 | D85: Lote Tiny House | E85: 116.72 | F85: 12.08m x 9.75m | G85: =E85*120 | H85: 59 | I85: 145 | J85: Disponible
A86: L085 | B86: Lote 85 | C86: M8 | D86: Lote Tiny House | E86: 116.88 | F86: 12.08m x 9.76m | G86: =E86*120 | H86: 59 | I86: 145 | J86: Disponible
...

Sheet Especificaciones Técnicas
B2: PARÁMETROS TÉCNICOS Y NORMAS CONSTRUCTIVAS
B3: Asociación Civil de Adjudicatarios Moon Paracas · Normativa Técnica
B5: 1. PARÁMETROS GEOTÉCNICOS Y CIMENTACIONES
B6: Parámetro Técnico | C6: Norma / Exigencia | D6: Sustentación de Ingeniería
B7: Clasificación Sísmica | C7: Zona Sísmica 4 (S1) | D7: Terreno de alta sismicidad según RNE E.030. Exige plateas de cimentación rígidas obligatorias para disipar esfuerzos sísmicos y evitar asentamientos diferenciales sobre arena.
B8: Resistencia de Cemento | C8: Cemento Portland Tipo V | D8: Presencia de sales y sulfatos en el suelo árido costero. El Cemento Tipo V garantiza inmunidad frente al ataque químico del salitre, asegurando una vida útil > 50 años.
B9: Resistencia del Concreto | C9: f'c >= 210 kg/cm² | D9: Mínimo especificado para todos los elementos estructurales y plateas de cimentación.
B10: Cota Topográfica Mínima | C10: 106.50 m s.n.m. (Ingreso) | D10: El emplazamiento en la meseta del tablazo elimina al 100% el riesgo sísmico por tsunami o subidas de marea.
B11: Cota Topográfica Máxima | C11: 113.50 m s.n.m. (Mirador) | D11: Gradiente topográfica suave de sur a norte (0.5% a 1%) que optimiza la evacuación de aguas de escorrentía pluvial.
B12: Diseño de Vías Internas | C12: Ancho de 6.00 metros | D12: Vías de tierra compactada estabilizada con emulsiones orgánicas para cero polvo. Restringidas exclusivamente a peatones, bicicletas y buggies eléctricos.
B15: 2. REGLAMENTO INTERNO DE CONSTRUCCIÓN Y ESTILO (ANEXO B)
B16: Elemento de Fachada | C16: Exigencia Estética | D16: Materiales Autorizados / Restricciones
B17: Muros y Fachadas | C17: Tonos terrosos y arena (Mimetismo desértico) | D17: Acabados en revoque rústico de barro texturizado, microcemento arena, u ocre. Se prohíben colores primarios brillantes o revestimientos metálicos industriales.
B18: Pircas de División | C18: Piedra de cantera local apilada a mano | D18: Muros bajos (máximo 1.20m de altura) para deslindar linderos, usando piedra caliza caliche dorada de Paracas. Prohibido cercos de alambre de púas o ladrillo expuesto sin tarrajeo.
B19: Pérgolas y Sombras | C19: Pórticos rústicos de madera noble | D19: Uso obligatorio de troncos o listones macizos de eucalipto seco tratado, caña brava o bambú chancado para terrazas y cocheras.
B20: Energía Autónoma | C20: Sistemas solares fotovoltaicos independientes | D20: Obligatoriedad de destinar un área en el techo plano para un mínimo de 4 paneles solares monocristalinos y baterías de litio. No se permite tendido eléctrico aéreo visible.
B21: Xeripaisajismo | C21: Uso de flora nativa de bajo consumo hídrico | D21: Vegetación obligatoria en linderos delanteros: Agaves americanos, cactus candelabro, huarangos y buganvilias. Prohibido el sembrado de césped americano que exija riego por inundación.

Sheet Presupuesto de Obras
B2: PRESUPUESTO DE INVERSIÓN EN OBRAS (CAPEX)
B3: Moon Paracas · Estimación técnica de infraestructura rústica de lujo
B5: 1. DETALLE DE PARTIDAS Y COSTOS DIRECTOS
B6: Item | C6: Descripción de Partida | D6: Unidad | E6: Metrado / Cantidad | F6: Precio Unitario (S/) | G6: Costo Total (S/) | H6: Materiales y Acabados Predominantes
B7: 01.00 | C7: TRABAJOS PRELIMINARES Y MOVIMIENTO DE TIERRAS | H7: Planificación e ingeniería base
B8: 01.01 | C8: Delimitación topográfica, replanteo de tizas e hitos | D8: glb | E8: 1 | F8: 15000 | G8: =E8*F8 | H8: Estacas de madera y teodolito
B9: 01.02 | C9: Movimiento de tierras, nivelación y compactado de vías | D9: m2 | E9: 17137.84 | F9: 6.5 | G9: =E9*F9 | H9: Uso de motoniveladora y rodillo en arena
B10: 02.00 | C10: INGRESO MONUMENTAL Y PÓRTICO DE ACCESO | H10: Acceso rústico e identidad visual
B11: 02.01 | C11: Pórtico monumental de troncos de eucalipto seco tratado | D11: glb | E11: 1 | F11: 45000 | G11: =E11*F11 | H11: Vigas y columnas de eucalipto seco de 8"-10"
B12: 02.02 | C12: Muros de pirca decorativa de piedra de cantera en pórtico | D12: m2 | E12: 120 | F12: 250 | G12: =E12*F12 | H12: Piedra caliza caliche dorada de Ica apilada
B13: 02.03 | C13: Caseta de vigilancia blindada y control de accesos | D13: und | E13: 1 | F13: 60000 | G13: =E13*F13 | H13: Estructura de concreto armado con cemento Tipo V
B14: 02.04 | C14: Portón rústico de madera shihuahuaco tratada para intemperie | D14: und | E14: 1 | F14: 15000 | G14: =E14*F14 | H14: Madera noble y herrajes de hierro forjado
B15: 03.00 | C15: CERCOS PERIMETRALES (PIRCAS DE SEGURIDAD) | H15: Protección perimetral integrada al paisaje
B16: 03.01 | C16: Cerco frontal de pirca de piedra natural (h=1.80m) | D16: m | E16: 450 | F16: 450 | G16: =E16*F16 | H16: Piedra caliza dorada de la región apilada a mano
B17: 03.02 | C17: Cerco de seguridad perimetral lateral y posterior ligero | D17: m | E17: 1200 | F17: 110 | G17: =E17*F17 | H17: Postes de eucalipto de 4" con alambre de púas
B18: 04.00 | C18: VÍAS INTERNAS Y CIRCULACIÓN (LIVING STREETS) | H18: Tránsito interno eco-eficiente
B19: 04.01 | C19: Afirmado y estabilización de vías con mezcla de arcilla y cal | D19: m2 | E19: 17137.84 | F19: 25 | G19: =E19*F19 | H19: Arcilla desértica compactada, libre de asfalto
B20: 04.02 | C20: Senderos peatonales ecológicos y alameda central | D20: m2 | E20: 3500 | F20: 18 | G20: =E20*F20 | H20: Arcilla fina compactada y bordes de piedra
B21: 05.00 | C21: CLUB OASIS Y ÁREAS RECREATIVAS COMUNES | H21: Corazón social y recreativo del condominio
B22: 05.01 | C22: Piscina Oasis central revestida con piedra de río | D22: m2 | E22: 395 | F22: 1200 | G22: =E22*F22 | H22: Revestimiento de piedra natural, filtros de cuarzo
B23: 05.02 | C23: Espejo de agua ornamental para relajación | D23: m2 | E23: 252 | F23: 650 | G23: =E23*F23 | H23: Lecho de piedra pulida y recirculación biológica
B24: 05.03 | C24: Decks de madera shihuahuaco tratada en zonas de descanso | D24: m2 | E24: 220 | F24: 380 | G24: =E24*F24 | H24: Madera machihembrada tratada contra intemperie
B25: 05.04 | C25: Fogón central (Fire Pit) integrado en piedra natural | D25: und | E25: 1 | F25: 25000 | G25: =E25*F25 | H25: Anillo de piedra con asientos integrados y gas
B26: 05.05 | C26: Xeripaisajismo y dunas ornamentales (cactus y agaves) | D26: glb | E26: 1 | F26: 50000 | G26: =E26*F26 | H26: Agave americano, cactus candelabro y bougainvilleas
B27: 06.00 | C27: INSTALACIONES SANITARIAS Y AGUA CONDOMINIAL | H27: Saneamiento ecológico e hídrico
B28: 06.01 | C28: Red de distribución de agua condominial a lotes | D28: m | E28: 2850 | F28: 85 | G28: =E28*F28 | H28: Tuberías de HDPE enterradas en zanja de arena
B29: 06.02 | C29: Cisterna central de almacenamiento de agua de 50m3 | D29: und | E29: 1 | F29: 120000 | G29: =E29*F29 | H29: Concreto armado Tipo V (protección de sulfatos)
B30: 06.03 | C30: Planta de Tratamiento de Aguas Residuales PTAR biológica | D30: und | E30: 1 | F30: 125000 | G30: =E30*F30 | H30: Sistema de lodos activos para reúso en riego
B31: 07.00 | C31: RED ELÉCTRICA ECO-SOLAR E ILUMINACIÓN COMÚN | H31: Iluminación limpia y carga limpia
B32: 07.01 | C32: Postes de iluminación vial autónomos con panel solar led | D32: und | E32: 95 | F32: 3500 | G32: =E32*F32 | H32: Postes de acero con luminaria led solar 60W
B33: 07.02 | C33: Pérgola fotovoltaica central y banco de baterías (Carga Buggy) | D33: glb | E33: 1 | F33: 120000 | G33: =E33*F33 | H33: Paneles solares monocristalinos y baterías de litio
C34: COSTO DIRECTO TOTAL DE OBRAS (CD) | G34: =SUM(G7:G33)
C35: Gastos Generales y Dirección Técnica (10%) | G35: =G34*0.1
C36: Utilidad del Contratista e Imprevistos (8%) | G36: =G34*0.08
C37: PRESUPUESTO TOTAL INVERSIÓN (CAPEX TOTAL) | G37: =G34+G35+G36
B39: Nota Técnica de Materiales: | C39: El presupuesto de obra civil se ha estimado con base en materiales rústicos de bajo mantenimiento y alta durabilidad para el desierto: - Piedra de Cantera local (pircas y muros de la caseta/pórtico), brindando estabilidad sísmica y aislamiento térmico natural. - Eucalipto seco tratado en troncos de 8"-10" y madera Shihuahuaco tratada para el pórtico, pérgolas, portón y decks. - Afirmado estabilizado en vías internas (cero asfalto) y postes led solares autónomos para un condominio de cero emisiones.

Sheet Flujo de Caja
B2: PROYECCIÓN DE FLUJO DE CAJA (HORIZONTE 24 MESES)
B3: Moon Paracas · Modelo de cobranza y pagos de obra por caja positiva
B5: 1. CRONOGRAMA DE VENTAS Y CRÉDITO DIRECTO (ENTRADAS Y SALIDAS DE CAJA)
B6: Mes | C6: Lotes Vend. | D6: P. Prom. Lote | E6: Ventas Lotes | F6: Coch. Vend. | G6: Ventas Coch. | H6: Ventas Totales | I6: Inicial Lotes (30%) | J6: Cobro Financ. (70%) | K6: Cocheras (100%) | L6: Total Ingresos | M6: CAPEX Obras | N6: Pago Terreno | O6: Comisiones (4%) | P6: Gtos. Admin/Leg | Q6: Total Egresos | R6: Flujo Neto | S6: Flujo Acumulado
B7: Mes 0 | C7: 0 | D7: 0 | E7: =C7*D7 | F7: 0 | G7: =F7*5000 | H7: =E7+G7 | I7: =E7*0.3 | J7: 0 | K7: =G7 | L7: =I7+J7+K7 | M7: 50000 | N7: 0 | O7: =H7*0.04 | P7: 0 | Q7: =M7+N7+O7+P7 | R7: =L7-Q7 | S7: =R7
B8: Mes 1 | C8: 13 | D8: 27445.15 | E8: =C8*D8 | F8: 6 | G8: =F8*5000 | H8: =E8+G8 | I8: =E8*0.3 | J8: 0 | K8: =G8 | L8: =I8+J8+K8 | M8: 150000 | N8: 37500 | O8: =H8*0.04 | P8: 15000 | Q8: =M8+N8+O8+P8 | R8: =L8-Q8 | S8: =S7+R8
B9: Mes 2 | C9: 13 | D9: 28567.62 | E9: =C9*D9 | F9: 6 | G9: =F9*5000 | H9: =E9+G9 | I9: =E9*0.3 | J9: =SUM(E8:E8)*0.7/12 | K9: =G9 | L9: =I9+J9+K9 | M9: 150000 | N9: 37500 | O9: =H9*0.04 | P9: 15000 | Q9: =M9+N9+O9+P9 | R9: =L9-Q9 | S9: =S8+R9
B10: Mes 3 | C10: 13 | D10: 18942 | E10: =C10*D10 | F10: 6 | G10: =F10*5000 | H10: =E10+G10 | I10: =E10*0.3 | J10: =SUM(E8:E9)*0.7/12 | K10: =G10 | L10: =I10+J10+K10 | M10: 150000 | N10: 37500 | O10: =H10*0.04 | P10: 15000 | Q10: =M10+N10+O10+P10 | R10: =L10-Q10 | S10: =S9+R10
B11: Mes 4 | C11: 16 | D11: 18544.75 | E11: =C11*D11 | F11: 6 | G11: =F11*5000 | H11: =E11+G11 | I11: =E11*0.3 | J11: =SUM(E8:E10)*0.7/12 | K11: =G11 | L11: =I11+J11+K11 | M11: 150000 | N11: 37500 | O11: =H11*0.04 | P11: 15000 | Q11: =M11+N11+O11+P11 | R11: =L11-Q11 | S11: =S10+R11
B12: Mes 5 | C12: 16 | D12: 12014.31 | E12: =C12*D12 | F12: 6 | G12: =F12*5000 | H12: =E12+G12 | I12: =E12*0.3 | J12: =SUM(E8:E11)*0.7/12 | K12: =G12 | L12: =I12+J12+K12 | M12: 150000 | N12: 37500 | O12: =H12*0.04 | P12: 15000 | Q12: =M12+N12+O12+P12 | R12: =L12-Q12 | S12: =S11+R12
B13: Mes 6 | C13: 16 | D13: 11832.38 | E13: =C13*D13 | F13: 6 | G13: =F13*5000 | H13: =E13+G13 | I13: =E13*0.3 | J13: =SUM(E8:E12)*0.7/12 | K13: =G13 | L13: =I13+J13+K13 | M13: 150000 | N13: 37500 | O13: =H13*0.04 | P13: 15000 | Q13: =M13+N13+O13+P13 | R13: =L13-Q13 | S13: =S12+R13
B14: Mes 7 | C14: 16 | D14: 11716.12 | E14: =C14*D14 | F14: 6 | G14: =F14*5000 | H14: =E14+G14 | I14: =E14*0.3 | J14: =SUM(E8:E13)*0.7/12 | K14: =G14 | L14: =I14+J14+K14 | M14: 130000 | N14: 37500 | O14: =H14*0.04 | P14: 15000 | Q14: =M14+N14+O14+P14 | R14: =L14-Q14 | S14: =S13+R14
B15: Mes 8 | C15: 16 | D15: 13842.62 | E15: =C15*D15 | F15: 6 | G15: =F15*5000 | H15: =E15+G15 | I15: =E15*0.3 | J15: =SUM(E8:E14)*0.7/12 | K15: =G15 | L15: =I15+J15+K15 | M15: 130000 | N15: 37500 | O15: =H15*0.04 | P15: 15000 | Q15: =M15+N15+O15+P15 | R15: =L15-Q15 | S15: =S14+R15
B16: Mes 9 | C16: 16 | D16: 22939.31 | E16: =C16*D16 | F16: 6 | G16: =F16*5000 | H16: =E16+G16 | I16: =E16*0.3 | J16: =SUM(E8:E15)*0.7/12 | K16: =G16 | L16: =I16+J16+K16 | M16: 130000 | N16: 37500 | O16: =H16*0.04 | P16: 15000 | Q16: =M16+N16+O16+P16 | R16: =L16-Q16 | S16: =S15+R16
B17: Mes 10 | C17: 16 | D17: 40012.5 | E17: =C17*D17 | F17: 6 | G17: =F17*5000 | H17: =E17+G17 | I17: =E17*0.3 | J17: =SUM(E8:E16)*0.7/12 | K17: =G17 | L17: =I17+J17+K17 | M17: 130000 | N17: 37500 | O17: =H17*0.04 | P17: 15000 | Q17: =M17+N17+O17+P17 | R17: =L17-Q17 | S17: =S16+R17
B18: Mes 11 | C18: 16 | D18: 39849.19 | E18: =C18*D18 | F18: 6 | G18: =F18*5000 | H18: =E18+G18 | I18: =E18*0.3 | J18: =SUM(E8:E17)*0.7/12 | K18: =G18 | L18: =I18+J18+K18 | M18: 130000 | N18: 37500 | O18: =H18*0.04 | P18: 15000 | Q18: =M18+N18+O18+P18 | R18: =L18-Q18 | S18: =S17+R18
B19: Mes 12 | C19: 16 | D19: 39078.06 | E19: =C19*D19 | F19: 6 | G19: =F19*5000 | H19: =E19+G19 | I19: =E19*0.3 | J19: =SUM(E8:E18)*0.7/12 | K19: =G19 | L19: =I19+J19+K19 | M19: 130000 | N19: 37500 | O19: =H19*0.04 | P19: 15000 | Q19: =M19+N19+O19+P19 | R19: =L19-Q19 | S19: =S18+R19
B20: Mes 13 | C20: 16 | D20: 13934.81 | E20: =C20*D20 | F20: 6 | G20: =F20*5000 | H20: =E20+G20 | I20: =E20*0.3 | J20: =SUM(E8:E19)*0.7/12 | K20: =G20 | L20: =I20+J20+K20 | M20: 150000 | N20: 37500 | O20: =H20*0.04 | P20: 15000 | Q20: =M20+N20+O20+P20 | R20: =L20-Q20 | S20: =S19+R20
B21: Mes 14 | C21: 16 | D21: 12975.31 | E21: =C21*D21 | F21: 6 | G21: =F21*5000 | H21: =E21+G21 | I21: =E21*0.3 | J21: =SUM(E9:E20)*0.7/12 | K21: =G21 | L21: =I21+J21+K21 | M21: 150000 | N21: 37500 | O21: =H21*0.04 | P21: 15000 | Q21: =M21+N21+O21+P21 | R21: =L21-Q21 | S21: =S20+R21
B22: Mes 15 | C22: 16 | D22: 12624.69 | E22: =C22*D22 | F22: 6 | G22: =F22*5000 | H22: =E22+G22 | I22: =E22*0.3 | J22: =SUM(E10:E21)*0.7/12 | K22: =G22 | L22: =I22+J22+K22 | M22: 150000 | N22: 37500 | O22: =H22*0.04 | P22: 15000 | Q22: =M22+N22+O22+P22 | R22: =L22-Q22 | S22: =S21+R22
B23: Mes 16 | C23: 16 | D23: 11093.56 | E23: =C23*D23 | F23: 6 | G23: =F23*5000 | H23: =E23+G23 | I23: =E23*0.3 | J23: =SUM(E11:E22)*0.7/12 | K23: =G23 | L23: =I23+J23+K23 | M23: 150000 | N23: 37500 | O23: =H23*0.04 | P23: 15000 | Q23: =M23+N23+O23+P23 | R23: =L23-Q23 | S23: =S22+R23
B24: Mes 17 | C24: 16 | D24: 14538.88 | E24: =C24*D24 | F24: 6 | G24: =F24*5000 | H24: =E24+G24 | I24: =E24*0.3 | J24: =SUM(E12:E23)*0.7/12 | K24: =G24 | L24: =I24+J24+K24 | M24: 150000 | N24: 37500 | O24: =H24*0.04 | P24: 15000 | Q24: =M24+N24+O24+P24 | R24: =L24-Q24 | S24: =S23+R24
B25: Mes 18 | C25: 16 | D25: 19410.25 | E25: =C25*D25 | F25: 6 | G25: =F25*5000 | H25: =E25+G25 | I25: =E25*0.3 | J25: =SUM(E13:E24)*0.7/12 | K25: =G25 | L25: =I25+J25+K25 | M25: 150000 | N25: 37500 | O25: =H25*0.04 | P25: 15000 | Q25: =M25+N25+O25+P25 | R25: =L25-Q25 | S25: =S24+R25
B26: Mes 19 | C26: 6 | D26: 20160 | E26: =C26*D26 | F26: 3 | G26: =F26*5000 | H26: =E26+G26 | I26: =E26*0.3 | J26: =SUM(E14:E25)*0.7/12 | K26: =G26 | L26: =I26+J26+K26 | M26: 95713.42 | N26: 37500 | O26: =H26*0.04 | P26: 15000 | Q26: =M26+N26+O26+P26 | R26: =L26-Q26 | S26: =S25+R26
B27: Mes 20 | C27: 6 | D27: 26374.17 | E27: =C27*D27 | F27: 3 | G27: =F27*5000 | H27: =E27+G27 | I27: =E27*0.3 | J27: =SUM(E15:E26)*0.7/12 | K27: =G27 | L27: =I27+J27+K27 | M27: 95713.42 | N27: 37500 | O27: =H27*0.04 | P27: 15000 | Q27: =M27+N27+O27+P27 | R27: =L27-Q27 | S27: =S26+R27
B28: Mes 21 | C28: 6 | D28: 27934.17 | E28: =C28*D28 | F28: 3 | G28: =F28*5000 | H28: =E28+G28 | I28: =E28*0.3 | J28: =SUM(E16:E27)*0.7/12 | K28: =G28 | L28: =I28+J28+K28 | M28: 95713.42 | N28: 37500 | O28: =H28*0.04 | P28: 15000 | Q28: =M28+N28+O28+P28 | R28: =L28-Q28 | S28: =S27+R28
B29: Mes 22 | C29: 6 | D29: 28171.5 | E29: =C29*D29 | F29: 3 | G29: =F29*5000 | H29: =E29+G29 | I29: =E29*0.3 | J29: =SUM(E17:E28)*0.7/12 | K29: =G29 | L29: =I29+J29+K29 | M29: 95713.42 | N29: 37500 | O29: =H29*0.04 | P29: 15000 | Q29: =M29+N29+O29+P29 | R29: =L29-Q29 | S29: =S28+R29
B30: Mes 23 | C30: 6 | D30: 29260.33 | E30: =C30*D30 | F30: 3 | G30: =F30*5000 | H30: =E30+G30 | I30: =E30*0.3 | J30: =SUM(E18:E29)*0.7/12 | K30: =G30 | L30: =I30+J30+K30 | M30: 95713.42 | N30: 37500 | O30: =H30*0.04 | P30: 15000 | Q30: =M30+N30+O30+P30 | R30: =L30-Q30 | S30: =S29+R30
B31: Mes 24 | C31: 3 | D31: 29409.67 | E31: =C31*D31 | F31: 2 | G31: =F31*5000 | H31: =E31+G31 | I31: =E31*0.3 | J31: =SUM(E19:E30)*0.7/12 | K31: =G31 | L31: =I31+J31+K31 | M31: 95713.42 | N31: 37500 | O31: =H31*0.04 | P31: 15000 | Q31: =M31+N31+O31+P31 | R31: =L31-Q31 | S31: =S30+R31
B32: TOTALES | C32: =SUM(C7:C31) | D32: =AVERAGE(D7:D31) | E32: =SUM(E7:E31) | F32: =SUM(F7:F31) | G32: =SUM(G7:G31) | H32: =SUM(H7:H31) | I32: =SUM(I7:I31) | J32: =SUM(J7:J31) | K32: =SUM(K7:K31) | L32: =SUM(L7:L31) | ... R32: =SUM(R7:R31) | S32: =S31
